Workbook
Name LecturerName: 'Выбор тем'!$B$4
Name ResponseDate: 'Выбор тем'!$F$4
Name SurveyVersion: 'Выбор тем'!$F$5
Name CompletionState: 'Выбор тем'!$B$5

Sheet Выбор тем
A1: КАКИЕ ТЕМЫ ВЫ ГОТОВЫ ЧИТАТЬ?
A2: Каталог тем · Rozum · Содержание внутри файла
A3: Укажите ФИО, откройте содержание и отметьте готовность. Заполняйте светло-зелёные ячейки.
A4: Ваше ФИО | E4: Дата анкеты
A5: Заполнение | B5: В процессе | E5: Версия | F5: ROZUM-2026-10-16-v2
A6: «Да» — готовы читать тему. При ограничениях по содержанию или программе выберите «Частично» и поясните их в комментарии.
A7: Все содержания → | D7: Инструкция →
A9: Код темы | B9: Тема | C9: В каких программах | D9: Содержание | E9: Могу читать | F9: Комментарий преподавателя
A10: T-69C6C7C7 | B10: Case Management в SOAR | C10: РКИОК | D10: Открыть →
A11: T-22B750DE | B11: DoS- и DDoS-кибератаки | C11: ТК | D11: Открыть →
A12: T-2AF2EE0F | B12: Internet of Things (IoT): архитектура, протоколы | C12: ОПКС | D12: Открыть →
A13: T-33E76F66 | B13: IP-адресация | C13: ОКМ | D13: Открыть →
A14: T-9917B01E | B14: OSINT-инструменты | C14: РКИОК | D14: Открыть →
A15: T-B82746ED | B15: SIEM: назначение, архитектура, нормализация и корреляция событий на базе Ntechnology SIEM | C15: РКИОК | D15: Открыть →
A16: T-BF0DCE22 | B16: SIEM-системы. Краткий обзор существующих решений. Сертифицированные open-source и коммерческие решения в Республике Беларусь | C16: ОКБО | D16: Открыть →
A17: T-2D7EF13A | B17: Suricata – установка, настройка, правила. Написание правил нормализации для Ntechnology SIEM (NTECH SIEM) | C17: РКИОК | D17: Открыть →
A18: T-18B4A131 | B18: Автоматизация и цифровизация административных процедур | C18: ЦТГУ | D18: Открыть →
A19: T-2C3B1F04 | B19: Автоматизация процессов обеспечения кибербезопасности с использованием систем класса SGRC | C19: ККС | D19: Открыть →
A20: T-E7C04975 | B20: Агрегация каналов и отказоустойчивость: STP, LACP, балансировка | C20: ОПКС | D20: Открыть →
A21: T-DA2CB29B | B21: Агрегация маршрутов | C21: ОКМ | D21: Открыть →
... A275: T-E90F5F72 | B275: Этапы действий ЦКБ: мониторинг, обнаружение, анализ, реагирование, восстановление | C275: ОКБО | D275: Открыть →
A277: Сохраните файл «Анкета_Фамилия.xlsx» и отправьте организатору ЛИЧНО. Других ответов преподавателей в этом файле нет.

Sheet Содержание тем
A1: СОДЕРЖАНИЕ ТЕМ
A2: Темы из УТП и программ. Ниже — фактические тексты источников; различающиеся варианты сохранены отдельно.
A3: ← К перечню тем
A5: Case Management в SOAR
A6: T-69C6C7C7 · Программы: РКИОК
A7: Вариант для: РКИОК
A8: Систематизация инцидентов: создание дел, назначение ответственных. Отслеживание статусов и результатов через встроенную систему управления делами. Интеграция с внешними сервис-десками и базами знаний.
A9: РКИОК — Реагирование на киберинциденты и отражение кибератак Раздел: Автоматизация обработки инцидентов · УТП: таблица 2, строка 60
A10: В программе: Тема 2. Case Management в SOAR (1 час лекции).
A11: Исходная программа РКИОК ↗ | D11: Исходный УТП РКИОК ↗
A12: =HYPERLINK("#'Выбор тем'!E"&MATCH("T-69C6C7C7",'Выбор тем'!$A:$A,0),"← Вернуться к теме")
A14: DoS- и DDoS-кибератаки
A15: T-22B750DE · Программы: ТК
A16: Вариант для: ТК
A17: DoS- и DDoS-кибератаки и их отличия. Виды DoS- и DDoS-кибератак. Классификация и цели DDoS-кибератак по уровням OSI. Атаки TCP-, UDP-, HTTP-flood. Способы защиты от DoS- и DDoS-кибератак.
A18: ТК — Технологии кибербезопасности: от spoofing-атак до VPN и межсетевых экранов Раздел: Практические аспекты обеспечения кибербезопасности корпоративных систем · УТП: таблица 2, строка 14
A19: В программе: Тема 2. DoS- и DDoS-кибератаки (2 часа лекции, 2 часа лабораторные занятия).
A20: Исходная программа ТК ↗ | D20: Исходный УТП ТК ↗
A21: =HYPERLINK("#'Выбор тем'!E"&MATCH("T-22B750DE",'Выбор тем'!$A:$A,0),"← Вернуться к теме")
A23: Internet of Things (IoT): архитектура, протоколы
A24: T-2AF2EE0F · Программы: ОПКС
A25: Вариант для: ОПКС
A26: Основные функции Internet of Things (IоT). Топология IoT, основные элементы, их функции. Процесс взаимодействия между сенсорными узлами (датчиками). Взаимодействие сервера IoT с приложением пользователя.
A27: ОПКС — Основы построения компьютерных сетей и обеспечения кибербезопасности Раздел: Основы построения компьютерных сетей · УТП: таблица 2, строка 16
A28: В программе: Тема 11. Internet of Things (IoT): архитектура, протоколы (2 часа лекции, 2 часа лабораторные занятия).
A29: Исходная программа ОПКС ↗ | D29: Исходный УТП ОПКС ↗
A30: =HYPERLINK("#'Выбор тем'!E"&MATCH("T-2AF2EE0F",'Выбор тем'!$A:$A,0),"← Вернуться к теме")
A32: IP-адресация
A33: T-33E76F66 · Программы: ОКМ
A34: Вариант для: ОКМ
A35: Структура IPv4- и IPv6-адресов. Представления IPv4- и IPv6-адресов в двоичной системе счисления. Определение адреса сети по IPv4-адресу и маске подсети. Определение сетевой и узловой части IPv4-адреса. Типы адресов IPv4- и IPv6-адресов. Отличие частных и публичных IPv4-адресов. Отличие классовой и бесклассовой IP-адресации. Бесклассовая IP-адресация. CIDR, VLSM. Принципы разбиения IPv4- и IPv6-сетей на подсети. Отличительные особенности разбиения на IPv4-сети и IPv6-сети.
A36: ОКМ — Основы обеспечения кибербезопасности. маршрутизация. IPv4- и IPv6-адресация Раздел: Маршрутизация. IPv4 и IPv6 адресация · УТП: таблица 2, строка 15
A37: В программе: Тема 1. IP-адресация (2 часа лекции, 2 часа лабораторные занятия).
A38: Исходная программа ОКМ ↗ | D38: Исходный УТП ОКМ ↗
A39: =HYPERLINK("#'Выбор тем'!E"&MATCH("T-33E76F66",'Выбор тем'!$A:$A,0),"← Вернуться к теме")
A41: OSINT-инструменты
A42: T-9917B01E · Программы: РКИОК
A43: Вариант для: РКИОК
A44: Понятие OSINT, его место в расследовании киберинцидентов. Типы источников данных. Основные категории OSINT-инструментов. Примеры использования OSINT при анализе инцидентов.
A45: РКИОК — Реагирование на киберинциденты и отражение кибератак Раздел: Введение в киберкриминалистику · УТП: таблица 2, строка 25
...

Sheet Инструкция
A1: ИНСТРУКЦИЯ
A3: 1 · Сохраните свою копию
A4: Откройте файл в Excel или LibreOffice Calc. Предварительный просмотр в чате может не поддерживать редактирование.
A6: 2 · Представьтесь
A7: Укажите ФИО полностью. Дату можно не заполнять.
A9: 3 · Посмотрите содержание
A10: Нажмите «Открыть →» напротив темы. Если тема встречается в нескольких программах, изучите соответствующие варианты. Интернет для содержания не нужен.
A12: 4 · Отметьте готовность
A13: «Да» — готовы читать тему в приведённом объёме. «Частично» — есть ограничения по содержанию или программе: поясните их в комментарии. Пустая отметка означает «не указано», а не отказ.
A15: 5 · Завершите и отправьте
A16: Выберите «Выбор завершён», сохраните свою копию как «Анкета_Фамилия.xlsx» и отправьте организатору лично. В общий чат предназначен только пустой шаблон.
A18: Что находится в каталоге
... A22: Темы без отдельного описания и несовпадения программы с УТП помечены в карточках. В ПСАЭ часть тем входит в общий практикум. Подробности — в отчёте проверки источников у организатора.
